<robot name = "robot">
    <link name="Link2">
        <inertial>
            <origin xyz="0 0 -0.43153855314003353" rpy="0 0 0"/>
            <mass value="1" />
            <inertia ixx="100" ixy="0" ixz="0" iyy="100" iyz="0" izz="100" />
        </inertial>
        <visual>
            <origin xyz="0 0 -0.43153855314003353" rpy="0 0 0"/>
            <geometry>
                <box size="0.8630771062800671 1.1479320442751715 1.0165851751973674" />
            </geometry>
            <material name="Green">
                <color rgba="0.0 1.0 0.0 1.0"/>
            </material>
        </visual>
        <collision>
            <origin xyz="0 0 -0.43153855314003353" rpy="0 0 0"/>
            <geometry>
                <box size="0.8630771062800671 1.1479320442751715 1.0165851751973674" />
            </geometry>
        </collision>
    </link>
    <joint name="Link2_Link1" type="revolute">
       <parent link="Link2"/>
       <child  link="Link1"/>
       <origin rpy="0 0 0" xyz="0.43153855314003353 0 -0.5082925875986837" />
       <axis xyz="0 1 0"/>
       <limit effort="0.0" lower="-3.14159" upper="3.14159" velocity="0.0"/>
    </joint>
    <link name="Link1">
        <inertial>
            <origin xyz="0.8146859190847162 0 0" rpy="0 0 0"/>
            <mass value="1" />
            <inertia ixx="100" ixy="0" ixz="0" iyy="100" iyz="0" izz="100" />
        </inertial>
        <visual>
            <origin xyz="0.8146859190847162 0 0" rpy="0 0 0"/>
            <geometry>
                <box size="1.6293718381694324 1.5300173621961333 1.1675770824009721" />
            </geometry>
            <material name="Blue">
                <color rgba="0.0 0.0 1.0 1.0"/>
            </material>
        </visual>
        <collision>
            <origin xyz="0.8146859190847162 0 0" rpy="0 0 0"/>
            <geometry>
                <box size="1.6293718381694324 1.5300173621961333 1.1675770824009721" />
            </geometry>
        </collision>
    </link>
    <joint name="Link1_Link6" type="revolute">
       <parent link="Link1"/>
       <child  link="Link6"/>
       <origin rpy="0 0 0" xyz="0 -0.7650086810980666 -0.5837885412004861" />
       <axis xyz="0 1 0"/>
       <limit effort="0.0" lower="-3.14159" upper="3.14159" velocity="0.0"/>
    </joint>
    <link name="Link6">
        <inertial>
            <origin xyz="0.5802137606747446 0 0" rpy="0 0 0"/>
            <mass value="1" />
            <inertia ixx="100" ixy="0" ixz="0" iyy="100" iyz="0" izz="100" />
        </inertial>
        <visual>
            <origin xyz="0.5802137606747446 0 0" rpy="0 0 0"/>
            <geometry>
                <box size="1.1604275213494892 2.255871458163117 1.042961228632861" />
            </geometry>
            <material name="Blue">
                <color rgba="0.0 0.0 1.0 1.0"/>
            </material>
        </visual>
        <collision>
            <origin xyz="0.5802137606747446 0 0" rpy="0 0 0"/>
            <geometry>
                <box size="1.1604275213494892 2.255871458163117 1.042961228632861" />
            </geometry>
        </collision>
    </link>
    <joint name="Link6_Link7" type="revolute">
       <parent link="Link6"/>
       <child  link="Link7"/>
       <origin rpy="0 0 0" xyz="0.5802137606747446 -1.1279357290815586 0" />
       <axis xyz="0 1 0"/>
       <limit effort="0.0" lower="-3.14159" upper="3.14159" velocity="0.0"/>
    </joint>
    <link name="Link7">
        <inertial>
            <origin xyz="0.5643961489838022 0 0" rpy="0 0 0"/>
            <mass value="1" />
            <inertia ixx="100" ixy="0" ixz="0" iyy="100" iyz="0" izz="100" />
        </inertial>
        <visual>
            <origin xyz="0.5643961489838022 0 0" rpy="0 0 0"/>
            <geometry>
                <box size="1.1287922979676044 1.0812310449997158 1.0676031006525502" />
            </geometry>
            <material name="Blue">
                <color rgba="0.0 0.0 1.0 1.0"/>
            </material>
        </visual>
        <collision>
            <origin xyz="0.5643961489838022 0 0" rpy="0 0 0"/>
            <geometry>
                <box size="1.1287922979676044 1.0812310449997158 1.0676031006525502" />
            </geometry>
        </collision>
    </link>
    <joint name="Link7_Link5" type="revolute">
       <parent link="Link7"/>
       <child  link="Link5"/>
       <origin rpy="0 0 0" xyz="0.5643961489838022 0 -0.5338015503262751" />
       <axis xyz="0 1 0"/>
       <limit effort="0.0" lower="-3.14159" upper="3.14159" velocity="0.0"/>
    </joint>
    <link name="Link5">
        <inertial>
            <origin xyz="0.9822645492293807 0 0" rpy="0 0 0"/>
            <mass value="1" />
            <inertia ixx="100" ixy="0" ixz="0" iyy="100" iyz="0" izz="100" />
        </inertial>
        <visual>
            <origin xyz="0.9822645492293807 0 0" rpy="0 0 0"/>
            <geometry>
                <box size="1.9645290984587613 1.776015718432605 1.1067577181312633" />
            </geometry>
            <material name="Green">
                <color rgba="0.0 1.0 0.0 1.0"/>
            </material>
        </visual>
        <collision>
            <origin xyz="0.9822645492293807 0 0" rpy="0 0 0"/>
            <geometry>
                <box size="1.9645290984587613 1.776015718432605 1.1067577181312633" />
            </geometry>
        </collision>
    </link>
    <joint name="Link5_Link4" type="revolute">
       <parent link="Link5"/>
       <child  link="Link4"/>
       <origin rpy="0 0 0" xyz="0.9822645492293807 0 -0.5533788590656317" />
       <axis xyz="0 1 0"/>
       <limit effort="0.0" lower="-3.14159" upper="3.14159" velocity="0.0"/>
    </joint>
    <link name="Link4">
        <inertial>
            <origin xyz="0.26423654173656475 0 0" rpy="0 0 0"/>
            <mass value="1" />
            <inertia ixx="100" ixy="0" ixz="0" iyy="100" iyz="0" izz="100" />
        </inertial>
        <visual>
            <origin xyz="0.26423654173656475 0 0" rpy="0 0 0"/>
            <geometry>
                <box size="0.5284730834731295 2.0834934893822123 1.1854184198755056" />
            </geometry>
            <material name="Green">
                <color rgba="0.0 1.0 0.0 1.0"/>
            </material>
        </visual>
        <collision>
            <origin xyz="0.26423654173656475 0 0" rpy="0 0 0"/>
            <geometry>
                <box size="0.5284730834731295 2.0834934893822123 1.1854184198755056" />
            </geometry>
        </collision>
    </link>
    <joint name="Link4_Link0" type="revolute">
       <parent link="Link4"/>
       <child  link="Link0"/>
       <origin rpy="0 0 0" xyz="0.26423654173656475 1.0417467446911062 0" />
       <axis xyz="0 1 0"/>
       <limit effort="0.0" lower="-3.14159" upper="3.14159" velocity="0.0"/>
    </joint>
    <link name="Link0">
        <inertial>
            <origin xyz="0.25496503407081506 0 0" rpy="0 0 0"/>
            <mass value="1" />
            <inertia ixx="100" ixy="0" ixz="0" iyy="100" iyz="0" izz="100" />
        </inertial>
        <visual>
            <origin xyz="0.25496503407081506 0 0" rpy="0 0 0"/>
            <geometry>
                <box size="0.5099300681416301 1.9858325745946652 1.4219679122796234" />
            </geometry>
            <material name="Blue">
                <color rgba="0.0 0.0 1.0 1.0"/>
            </material>
        </visual>
        <collision>
            <origin xyz="0.25496503407081506 0 0" rpy="0 0 0"/>
            <geometry>
                <box size="0.5099300681416301 1.9858325745946652 1.4219679122796234" />
            </geometry>
        </collision>
    </link>
    <joint name="Link0_Link3" type="revolute">
       <parent link="Link0"/>
       <child  link="Link3"/>
       <origin rpy="0 0 0" xyz="0 1.9858325745946652 0" />
       <axis xyz="0 1 0"/>
       <limit effort="0.0" lower="-3.14159" upper="3.14159" velocity="0.0"/>
    </joint>
    <link name="Link3">
        <inertial>
            <origin xyz="0.4324945749067137 0 0" rpy="0 0 0"/>
            <mass value="1" />
            <inertia ixx="100" ixy="0" ixz="0" iyy="100" iyz="0" izz="100" />
        </inertial>
        <visual>
            <origin xyz="0.4324945749067137 0 0" rpy="0 0 0"/>
            <geometry>
                <box size="0.8649891498134274 1.2130893034702082 1.0661164571262307" />
            </geometry>
            <material name="Blue">
                <color rgba="0.0 0.0 1.0 1.0"/>
            </material>
        </visual>
        <collision>
            <origin xyz="0.4324945749067137 0 0" rpy="0 0 0"/>
            <geometry>
                <box size="0.8649891498134274 1.2130893034702082 1.0661164571262307" />
            </geometry>
        </collision>
    </link>
</robot>