<robot name = "robot">
    <link name="Link0">
        <inertial>
            <origin xyz="0 0 1.5" rpy="0 0 0"/>
            <mass value="1" />
            <inertia ixx="100" ixy="0" ixz="0" iyy="100" iyz="0" izz="100" />
        </inertial>
        <visual>
            <origin xyz="0 0 1.5" rpy="0 0 0"/>
            <geometry>
                <box size="1 1 1" />
            </geometry>
            <material name="Green">
                <color rgba="0.0 1.0 0.0 1.0"/>
            </material>
        </visual>
        <collision>
            <origin xyz="0 0 1.5" rpy="0 0 0"/>
            <geometry>
                <box size="1 1 1" />
            </geometry>
        </collision>
    </link>
    <joint name="Link0_Link1" type="revolute">
       <parent link="Link0"/>
       <child  link="Link1"/>
       <origin rpy="0 0 0" xyz="0 -0.5 1" />
     <axis xyz="1 0 0"/>
       <limit effort="0.0" lower="-3.14159" upper="3.14159" velocity="0.0"/>
    </joint>
    <link name="Link1">
        <inertial>
            <origin xyz="0 -0.5215571480455777 0" rpy="0 0 0"/>
            <mass value="1" />
            <inertia ixx="100" ixy="0" ixz="0" iyy="100" iyz="0" izz="100" />
        </inertial>
        <visual>
            <origin xyz="0 -0.5215571480455777 0" rpy="0 0 0"/>
            <geometry>
                <box size="0.8153165213336812 1.0431142960911555 0.12766995280502216" />
            </geometry>
            <material name="Green">
                <color rgba="0.0 1.0 0.0 1.0"/>
            </material>
        </visual>
        <collision>
            <origin xyz="0 -0.5215571480455777 0" rpy="0 0 0"/>
            <geometry>
                <box size="0.8153165213336812 1.0431142960911555 0.12766995280502216" />
            </geometry>
        </collision>
    </link>
    <joint name="Link0_Link2" type="revolute">
       <parent link="Link0"/>
       <child  link="Link2"/>
       <origin rpy="0 0 0" xyz="0.5 0 1" />
     <axis xyz="0 1 0"/>
       <limit effort="0.0" lower="-3.14159" upper="3.14159" velocity="0.0"/>
    </joint>
    <link name="Link2">
        <inertial>
            <origin xyz="0.43003090716642167 0 0" rpy="0 0 0"/>
            <mass value="1" />
            <inertia ixx="100" ixy="0" ixz="0" iyy="100" iyz="0" izz="100" />
        </inertial>
        <visual>
            <origin xyz="0.43003090716642167 0 0" rpy="0 0 0"/>
            <geometry>
                <box size="0.8600618143328433 0.8293267693940193 0.9678578064494086" />
            </geometry>
            <material name="Blue">
                <color rgba="0.0 0.0 1.0 1.0"/>
            </material>
        </visual>
        <collision>
            <origin xyz="0.43003090716642167 0 0" rpy="0 0 0"/>
            <geometry>
                <box size="0.8600618143328433 0.8293267693940193 0.9678578064494086" />
            </geometry>
        </collision>
    </link>
    <joint name="Link2_Link3" type="revolute">
       <parent link="Link2"/>
       <child  link="Link3"/>
       <origin rpy="0 0 0" xyz="0 0 0.4839289032247043" />
     <axis xyz="0 0 1"/>
       <limit effort="0.0" lower="-3.14159" upper="3.14159" velocity="0.0"/>
    </joint>
    <link name="Link3">
        <inertial>
            <origin xyz="0 0 0.06645674180474272" rpy="0 0 0"/>
            <mass value="1" />
            <inertia ixx="100" ixy="0" ixz="0" iyy="100" iyz="0" izz="100" />
        </inertial>
        <visual>
            <origin xyz="0 0 0.06645674180474272" rpy="0 0 0"/>
            <geometry>
                <box size="0.6330203075163148 0.48185380233716013 0.13291348360948543" />
            </geometry>
            <material name="Blue">
                <color rgba="0.0 0.0 1.0 1.0"/>
            </material>
        </visual>
        <collision>
            <origin xyz="0 0 0.06645674180474272" rpy="0 0 0"/>
            <geometry>
                <box size="0.6330203075163148 0.48185380233716013 0.13291348360948543" />
            </geometry>
        </collision>
    </link>
    <joint name="Link3_Link4" type="revolute">
       <parent link="Link3"/>
       <child  link="Link4"/>
       <origin rpy="0 0 0" xyz="0 0 0.06645674180474272" />
     <axis xyz="0 0 1"/>
       <limit effort="0.0" lower="-3.14159" upper="3.14159" velocity="0.0"/>
    </joint>
    <link name="Link4">
        <inertial>
            <origin xyz="0 0 0.30350833753426626" rpy="0 0 0"/>
            <mass value="1" />
            <inertia ixx="100" ixy="0" ixz="0" iyy="100" iyz="0" izz="100" />
        </inertial>
        <visual>
            <origin xyz="0 0 0.30350833753426626" rpy="0 0 0"/>
            <geometry>
                <box size="0.6256443572027992 0.8421034346280386 0.6070166750685325" />
            </geometry>
            <material name="Green">
                <color rgba="0.0 1.0 0.0 1.0"/>
            </material>
        </visual>
        <collision>
            <origin xyz="0 0 0.30350833753426626" rpy="0 0 0"/>
            <geometry>
                <box size="0.6256443572027992 0.8421034346280386 0.6070166750685325" />
            </geometry>
        </collision>
    </link>
    <joint name="Link4_Link5" type="revolute">
       <parent link="Link4"/>
       <child  link="Link5"/>
       <origin rpy="0 0 0" xyz="-0.6256443572027992 0 0" />
     <axis xyz="0 1 0"/>
       <limit effort="0.0" lower="-3.14159" upper="3.14159" velocity="0.0"/>
    </joint>
    <link name="Link5">
        <inertial>
            <origin xyz="-0.10954704372856107 0 0" rpy="0 0 0"/>
            <mass value="1" />
            <inertia ixx="100" ixy="0" ixz="0" iyy="100" iyz="0" izz="100" />
        </inertial>
        <visual>
            <origin xyz="-0.10954704372856107 0 0" rpy="0 0 0"/>
            <geometry>
                <box size="0.21909408745712214 0.48928092413710966 0.3526777319034543" />
            </geometry>
            <material name="Blue">
                <color rgba="0.0 0.0 1.0 1.0"/>
            </material>
        </visual>
        <collision>
            <origin xyz="-0.10954704372856107 0 0" rpy="0 0 0"/>
            <geometry>
                <box size="0.21909408745712214 0.48928092413710966 0.3526777319034543" />
            </geometry>
        </collision>
    </link>
    <joint name="Link0_Link6" type="revolute">
       <parent link="Link0"/>
       <child  link="Link6"/>
       <origin rpy="0 0 0" xyz="0 -0.5 1" />
     <axis xyz="1 0 0"/>
       <limit effort="0.0" lower="-3.14159" upper="3.14159" velocity="0.0"/>
    </joint>
    <link name="Link6">
        <inertial>
            <origin xyz="0 -0.13006444253493865 0" rpy="0 0 0"/>
            <mass value="1" />
            <inertia ixx="100" ixy="0" ixz="0" iyy="100" iyz="0" izz="100" />
        </inertial>
        <visual>
            <origin xyz="0 -0.13006444253493865 0" rpy="0 0 0"/>
            <geometry>
                <box size="0.6965865639343479 0.2601288850698773 0.9161160361307602" />
            </geometry>
            <material name="Blue">
                <color rgba="0.0 0.0 1.0 1.0"/>
            </material>
        </visual>
        <collision>
            <origin xyz="0 -0.13006444253493865 0" rpy="0 0 0"/>
            <geometry>
                <box size="0.6965865639343479 0.2601288850698773 0.9161160361307602" />
            </geometry>
        </collision>
    </link>
    <joint name="Link4_Link7" type="revolute">
       <parent link="Link4"/>
       <child  link="Link7"/>
       <origin rpy="0 0 0" xyz="0 0 0.30350833753426626" />
     <axis xyz="0 0 1"/>
       <limit effort="0.0" lower="-3.14159" upper="3.14159" velocity="0.0"/>
    </joint>
    <link name="Link7">
        <inertial>
            <origin xyz="0 0 0.0906666466882002" rpy="0 0 0"/>
            <mass value="1" />
            <inertia ixx="100" ixy="0" ixz="0" iyy="100" iyz="0" izz="100" />
        </inertial>
        <visual>
            <origin xyz="0 0 0.0906666466882002" rpy="0 0 0"/>
            <geometry>
                <box size="0.70589245684393 0.5901368284682497 0.1813332933764004" />
            </geometry>
            <material name="Green">
                <color rgba="0.0 1.0 0.0 1.0"/>
            </material>
        </visual>
        <collision>
            <origin xyz="0 0 0.0906666466882002" rpy="0 0 0"/>
            <geometry>
                <box size="0.70589245684393 0.5901368284682497 0.1813332933764004" />
            </geometry>
        </collision>
    </link>
</robot>